<mujoco model="ant-box">
  <asset>
    <!-- <texture name="skybox" type="skybox" builtin="flat" rgb1="1 1 1" width="800" height="800" />
    <texture name="grid" type="2d" builtin="flat" rgb1="0.8 0.8 0.8" width="300" height="300" mark="edge"/>
    <material name="grid" texture="grid"/>
    <material name="self" rgba=".7 .5 .3 1"/> -->
    <texture name="skybox" type="skybox" builtin="gradient" rgb1=".2 .3 .4" rgb2="0 0 0" width="800" height="800" mark="random" markrgb="1 1 1"/>
    <texture name="grid" type="2d" builtin="checker" rgb1=".2 .1 .2" rgb2=".3 .2 .3" width="300" height="300" mark="edge" markrgb=".3 .2 .3"/>
    <material name="grid" texture="grid" texrepeat="1 1" texuniform="true" reflectance=".2"/>
    <material name="self" rgba=".7 .5 .3 1"/>
  </asset>
  <visual>
    <headlight ambient=".4 .4 .4" diffuse=".8 .8 .8" specular="0.1 0.1 0.1"/>
    <map znear=".001"/>
    <quality shadowsize="16384"/>
  </visual>
  <compiler angle="degree" coordinate="global" inertiafromgeom="true"/>
  <option integrator="RK4" timestep="0.01"/>
  <default>
    <joint armature="1" damping="1" limited="true"/>
    <geom conaffinity="0" condim="3" density="5.0" friction="1 0.5 0.5" margin="0.01" rgba=".7 .5 .3 1"/>
  </default>
  <worldbody>
    <light cutoff="100" diffuse="1 1 1" dir="0.3 0 -1.3" directional="true" exponent="1" pos="-30 0 130" specular=".1 .1 .1"/>
    <geom conaffinity="1" condim="3" name="floor" pos="0 0 0" rgba="1 1 1 1" size="200 200 .125" type="plane" material="grid"/>
    <body name="0" pos="0 0 0">
      <camera name="track" mode="trackcom" pos="0 -3 0.3" xyaxes="1 0 0 0 0 1"/>
      <geom pos="0 0 0" size="0.25" type="sphere"/>
      <joint armature="0" damping="0" limited="false" margin="0.01" name="root" pos="0 0 0" type="free"/>
      <body name="1" pos="0 0 0">
        <joint axis="-0.707107 0.707107 0" name="1_joint" pos="0 0 0" range="-30 30" type="hinge"/>
        <geom fromto="0 0 0 0.4 0.4 0" size="0.08" type="capsule"/>
      </body>
      <body name="2" pos="0 0 0">
        <joint axis="-0.707107 -0.707107 0" name="2_joint" pos="0 0 0" range="-30 30" type="hinge"/>
        <geom fromto="0 0 0 -0.4 0.4 0" size="0.08" type="capsule"/>
      </body>
      <body name="3" pos="0 0 0">
        <joint axis="0.707107 -0.707107 0" name="3_joint" pos="0 0 0" range="-30 30" type="hinge"/>
        <geom fromto="0 0 0 -0.4 -0.4 0" size="0.08" type="capsule"/>
      </body>
      <body name="4" pos="0 0 0">
        <joint axis="0.707107 0.707107 0" name="4_joint" pos="0 0 0" range="-30 30" type="hinge"/>
        <geom fromto="0 0 0 0.4 -0.4 0" size="0.08" type="capsule"/>
      </body>
    </body>
    <body name="box" pos="0 0 0">
      <freejoint name="box_joint"/>
      <geom type="box" size="0.5 0.5 0.5" rgba="0.2 0.6 0.9 1"
            contype="1" conaffinity="1" density="0.001" friction="1 0.005 0.0001"/>
    </body>
  </worldbody>
  <actuator>
    <motor ctrllimited="true" ctrlrange="-1.0 1.0" joint="1_joint" gear="150" name="1_joint"/>
    <motor ctrllimited="true" ctrlrange="-1.0 1.0" joint="2_joint" gear="150" name="2_joint"/>
    <motor ctrllimited="true" ctrlrange="-1.0 1.0" joint="3_joint" gear="150" name="3_joint"/>
    <motor ctrllimited="true" ctrlrange="-1.0 1.0" joint="4_joint" gear="150" name="4_joint"/>
  </actuator>
</mujoco>
