<mujoco model="swimmer">
  <asset>
    <!-- <texture name="skybox" type="skybox" builtin="flat" rgb1="1 1 1" width="800" height="800" />
    <texture name="grid" type="2d" builtin="flat" rgb1="0.8 0.8 0.8" width="300" height="300" mark="edge"/>
    <material name="grid" texture="grid"/>
    <material name="self" rgba=".7 .5 .3 1"/> -->
    <texture name="skybox" type="skybox" builtin="gradient" rgb1=".2 .3 .4" rgb2="0 0 0" width="800" height="800" mark="random" markrgb="1 1 1"/>
    <texture name="grid" type="2d" builtin="checker" rgb1=".1 .2 .2" rgb2=".2 .3 .3" width="300" height="300" mark="edge" markrgb=".2 .3 .3"/>
    <material name="grid" texture="grid" texrepeat="1 1" texuniform="true" reflectance=".2"/>
    <material name="self" rgba=".7 .5 .3 1"/>
  </asset>
  <visual>
    <headlight ambient=".4 .4 .4" diffuse=".8 .8 .8" specular="0.1 0.1 0.1"/>
    <map znear=".001"/>
    <quality shadowsize="16384"/>
  </visual>
  <compiler angle="degree" coordinate="global" inertiafromgeom="true"/>
  <option density="4000" integrator="RK4" timestep="0.01" viscosity="0.1"/>
  <default>
    <geom conaffinity="0" condim="1" margin="0.001" rgba=".7 .5 .3 1"/>
    <joint armature="0.1"/>
  </default>
  <worldbody>
    <light cutoff="100" diffuse="1 1 1" dir="0 -0.3 -1.3" directional="true" exponent="1" pos="0 30 130" specular=".1 .1 .1"/>
    <geom conaffinity="0" condim="3" name="floor" pos="0 0 -0.1" rgba="1 1 1 1" size="40 40 0.1" type="plane" material="grid"/>
    <body name="0" pos="0 0 0">
      <camera name="track" mode="trackcom" pos="0 -7 7" xyaxes="1 0 0 0 1 1"/>
      <joint axis="1 0 0" name="slider1" pos="0 0 0" type="slide"/>
      <joint axis="0 1 0" name="slider2" pos="0 0 0" type="slide"/>
      <joint axis="0 0 1" name="0_joint" pos="0 0 0" type="hinge"/>
      <geom density="1000" fromto="0 0 0 0 -1 0" size="0.08" type="capsule"/>
      <body name="1" pos="0 -1 0">
        <joint axis="0 0 1" limited="true" name="1_joint" pos="0 -1 0" range="-100 100" type="hinge"/>
        <geom density="1000" fromto="0 -1 0 0 -2 0" size="0.08" type="capsule"/>
      </body>
    </body>
  </worldbody>
  <actuator>
    <motor ctrllimited="true" ctrlrange="-1 1" gear="150" joint="1_joint" name="1_joint"/>
  </actuator>
</mujoco>
