<mujoco model="walker">
  <asset>
    <!-- <texture name="skybox" type="skybox" builtin="flat" rgb1="1 1 1" width="800" height="800" />
    <texture name="grid" type="2d" builtin="flat" rgb1="0.8 0.8 0.8" width="300" height="300" mark="edge"/>
    <material name="grid" texture="grid"/>
    <material name="self" rgba=".7 .5 .3 1"/> -->
    <texture name="skybox" type="skybox" builtin="gradient" rgb1=".2 .3 .4" rgb2="0 0 0" width="800" height="800" mark="random" markrgb="1 1 1"/>
    <texture name="grid" type="2d" builtin="checker" rgb1=".1 .2 .3" rgb2=".2 .3 .4" width="300" height="300" mark="edge" markrgb=".2 .3 .4"/>
    <material name="grid" texture="grid" texrepeat="1 1" texuniform="true" reflectance=".2"/>
    <material name="self" rgba=".7 .5 .3 1"/>
  </asset>
  <visual>
    <headlight ambient=".4 .4 .4" diffuse=".8 .8 .8" specular="0.1 0.1 0.1"/>
    <map znear=".001"/>
    <quality shadowsize="16384"/>
  </visual>
  <compiler angle="degree" coordinate="global" inertiafromgeom="true"/>
  <default>
    <joint armature="1" damping="1" limited="true"/>
    <geom conaffinity="0" condim="1" margin="0.001" solimp=".8 .8 .01" solref=".02 1" rgba=".7 .5 .3 1"/>
    <motor ctrllimited="true" ctrlrange="-.4 .4"/>
  </default>
  <option integrator="RK4" timestep="0.002"/>
  <worldbody>
    <light cutoff="100" diffuse="1 1 1" dir="0 -0.3 -1.3" directional="true" exponent="1" pos="0 30 130" specular=".1 .1 .1"/>
    <geom conaffinity="1" condim="3" name="floor" pos="0 0 0" rgba="1 1 1 1" size="200 200 .125" type="plane" material="grid"/>
    <body name="0" pos="0 0 1.25">
      <camera name="track" mode="trackcom" pos="0 -10 5" quat="0.831 0.556 0 0"/>
      <joint armature="0" axis="1 0 0" damping="0" limited="false" name="rootx" pos="0 0 0" stiffness="0" type="slide"/>
      <joint armature="0" axis="0 0 1" damping="0" limited="false" name="rootz" pos="0 0 0" ref="1.25" stiffness="0" type="slide"/>
      <joint armature="0" axis="0 1 0" damping="0" limited="false" name="0_joint" pos="0 0 1.25" stiffness="0" type="hinge"/>
      <geom friction="0.9" fromto="-0 0 1.45 0 0 1.05" size="0.05" type="capsule"/>
      <body name="1" pos="0 0 1.05">
        <joint axis="0 -1 0" name="1_joint" pos="0 0 1.05" range="-180 180" type="hinge"/>
        <geom friction="2.0" fromto="0 0 1.05 0 0 0.6" size="0.05" type="capsule"/>
      </body>
      <body name="2" pos="0 0 1.05">
        <joint axis="0 -1 0" name="2_joint" pos="0 0 1.05" range="-180 180" type="hinge"/>
        <geom friction="2.0" fromto="0 0 1.05 0 0 0.6" size="0.05" type="capsule"/>
      </body>
    </body>
  </worldbody>
  <actuator>
    <motor ctrllimited="true" ctrlrange="-1.0 1.0" gear="200" joint="1_joint" name="1_joint"/>
    <motor ctrllimited="true" ctrlrange="-1.0 1.0" gear="200" joint="2_joint" name="2_joint"/>
  </actuator>
</mujoco>
